"""
Unit tests for error handling and recovery mechanisms.
"""

import json
import time
from unittest.mock import Mock, patch

import pytest

from tests.fixtures.test_data import ERROR_SCENARIOS


@pytest.mark.unit
class TestErrorClassification:
    """Test error classification and categorization."""

    def test_classify_rate_limit_error(self):
        """Test rate limit error classification."""

        def classify_error(error_message):
            if "rate limit" in error_message.lower():
                return "rate_limit"
            elif "authentication" in error_message.lower():
                return "auth_error"
            elif "timeout" in error_message.lower():
                return "timeout"
            else:
                return "unknown"

        assert classify_error("Rate limit exceeded") == "rate_limit"
        assert classify_error("RATE LIMIT ERROR") == "rate_limit"
        assert classify_error("Invalid authentication") == "auth_error"
        assert classify_error("Request timeout") == "timeout"
        assert classify_error("Unknown error") == "unknown"

    def test_retryable_error_detection(self):
        """Test detection of retryable vs non-retryable errors."""

        def is_retryable(error_type):
            retryable_errors = ["rate_limit", "timeout", "server_error", "network_error"]
            non_retryable_errors = ["auth_error", "validation_error", "quota_exceeded"]

            if error_type in retryable_errors:
                return True
            elif error_type in non_retryable_errors:
                return False
            else:
                return False  # Conservative: don't retry unknown errors

        # Retryable errors
        assert is_retryable("rate_limit") == True
        assert is_retryable("timeout") == True
        assert is_retryable("server_error") == True

        # Non-retryable errors
        assert is_retryable("auth_error") == False
        assert is_retryable("validation_error") == False
        assert is_retryable("quota_exceeded") == False

        # Unknown errors
        assert is_retryable("unknown_error") == False

    def test_error_severity_levels(self):
        """Test error severity classification."""

        def get_error_severity(error_type):
            severity_map = {
                "validation_error": "low",
                "rate_limit": "medium",
                "timeout": "medium",
                "auth_error": "high",
                "quota_exceeded": "high",
                "server_error": "critical",
            }
            return severity_map.get(error_type, "medium")

        assert get_error_severity("validation_error") == "low"
        assert get_error_severity("rate_limit") == "medium"
        assert get_error_severity("auth_error") == "high"
        assert get_error_severity("server_error") == "critical"


@pytest.mark.unit
class TestRetryMechanisms:
    """Test retry logic and backoff strategies."""

    def test_exponential_backoff(self):
        """Test exponential backoff calculation."""

        def calculate_backoff(attempt, base_delay=1.0, max_delay=60.0):
            delay = base_delay * (2**attempt)
            return min(delay, max_delay)

        # Test exponential growth
        assert calculate_backoff(0) == 1.0  # 1 * 2^0
        assert calculate_backoff(1) == 2.0  # 1 * 2^1
        assert calculate_backoff(2) == 4.0  # 1 * 2^2
        assert calculate_backoff(3) == 8.0  # 1 * 2^3

        # Test max delay cap
        assert calculate_backoff(10) == 60.0  # Capped at max_delay

    def test_retry_with_jitter(self):
        """Test retry delays with jitter to avoid thundering herd."""
        import random

        def calculate_backoff_with_jitter(attempt, base_delay=1.0, jitter_factor=0.1):
            base_backoff = base_delay * (2**attempt)
            jitter = random.uniform(-jitter_factor, jitter_factor) * base_backoff
            return max(0.1, base_backoff + jitter)  # Minimum 100ms

        # Test that jitter is applied (multiple calls should give different results)
        delays = [calculate_backoff_with_jitter(2) for _ in range(10)]

        # All delays should be around 4.0 seconds but vary
        for delay in delays:
            assert 3.6 <= delay <= 4.4  # Within jitter range

        # Not all delays should be identical
        assert len(set([round(d, 2) for d in delays])) > 1

    def test_retry_decorator_simulation(self):
        """Test retry decorator logic."""

        def retry_on_failure(max_retries=3, backoff_factor=1.0):
            def decorator(func):
                def wrapper(*args, **kwargs):
                    last_exception = None

                    for attempt in range(max_retries + 1):
                        try:
                            return func(*args, **kwargs)
                        except Exception as e:
                            last_exception = e

                            if attempt < max_retries:
                                delay = backoff_factor * (2**attempt)
                                time.sleep(min(delay, 0.1))  # Cap for test speed
                            else:
                                raise last_exception

                return wrapper

            return decorator

        # Test successful retry
        attempt_counter = {"count": 0}

        @retry_on_failure(max_retries=2)
        def flaky_function():
            attempt_counter["count"] += 1
            if attempt_counter["count"] < 3:
                raise Exception("Temporary failure")
            return "success"

        result = flaky_function()
        assert result == "success"
        assert attempt_counter["count"] == 3  # Failed twice, succeeded on third

    def test_circuit_breaker_pattern(self):
        """Test circuit breaker implementation."""

        class CircuitBreaker:
            def __init__(self, failure_threshold=3, timeout=60):
                self.failure_threshold = failure_threshold
                self.timeout = timeout
                self.failure_count = 0
                self.last_failure_time = None
                self.state = "closed"  # closed, open, half_open

            def call(self, func, *args, **kwargs):
                if self.state == "open":
                    if time.time() - self.last_failure_time > self.timeout:
                        self.state = "half_open"
                    else:
                        raise Exception("Circuit breaker is open")

                try:
                    result = func(*args, **kwargs)
                    if self.state == "half_open":
                        self.reset()
                    return result
                except Exception as e:
                    self.record_failure()
                    raise e

            def record_failure(self):
                self.failure_count += 1
                self.last_failure_time = time.time()

                if self.failure_count >= self.failure_threshold:
                    self.state = "open"

            def reset(self):
                self.failure_count = 0
                self.last_failure_time = None
                self.state = "closed"

        # Test circuit breaker behavior
        breaker = CircuitBreaker(failure_threshold=2, timeout=0.1)

        def failing_function():
            raise Exception("Always fails")

        # First failures should go through
        with pytest.raises(Exception):
            breaker.call(failing_function)
        assert breaker.state == "closed"

        with pytest.raises(Exception):
            breaker.call(failing_function)
        assert breaker.state == "open"  # Circuit opened after 2 failures

        # Further calls should be blocked
        with pytest.raises(Exception, match="Circuit breaker is open"):
            breaker.call(failing_function)


@pytest.mark.unit
class TestErrorRecovery:
    """Test error recovery strategies."""

    def test_fallback_provider_selection(self, mock_all_providers):
        """Test fallback to alternative providers."""
        providers = list(mock_all_providers.values())

        # Simulate primary provider failure
        providers[0].generate = Mock(side_effect=Exception("Primary failed"))

        def try_providers_with_fallback(prompt, providers_list):
            for i, provider in enumerate(providers_list):
                try:
                    return provider.generate(prompt), i
                except Exception as e:
                    if i == len(providers_list) - 1:  # Last provider
                        raise e
                    continue

        result, provider_index = try_providers_with_fallback("Test", providers)

        assert result is not None
        assert provider_index == 1  # Used second provider

    def test_graceful_degradation(self):
        """Test graceful degradation when services are unavailable."""

        def get_response_with_degradation(provider_available=True, cache_available=True):
            if provider_available:
                return {"source": "live", "response": "Live response"}
            elif cache_available:
                return {"source": "cache", "response": "Cached response"}
            else:
                return {"source": "fallback", "response": "Default response"}

        # Normal operation
        result = get_response_with_degradation(True, True)
        assert result["source"] == "live"

        # Provider down, use cache
        result = get_response_with_degradation(False, True)
        assert result["source"] == "cache"

        # Everything down, use fallback
        result = get_response_with_degradation(False, False)
        assert result["source"] == "fallback"

    def test_partial_failure_handling(self):
        """Test handling of partial batch failures."""

        def process_batch_with_recovery(items, processor):
            results = []
            errors = []

            for i, item in enumerate(items):
                try:
                    result = processor(item)
                    results.append({"index": i, "result": result, "status": "success"})
                except Exception as e:
                    errors.append({"index": i, "item": item, "error": str(e), "status": "failed"})
                    results.append({"index": i, "result": None, "status": "failed"})

            return {
                "results": results,
                "errors": errors,
                "success_count": len([r for r in results if r["status"] == "success"]),
                "failure_count": len(errors),
            }

        # Simulate processor that fails on even indices
        def flaky_processor(item):
            if item % 2 == 0:
                raise Exception(f"Failed on item {item}")
            return f"processed_{item}"

        items = [1, 2, 3, 4, 5]
        result = process_batch_with_recovery(items, flaky_processor)

        assert result["success_count"] == 3  # items 1, 3, 5
        assert result["failure_count"] == 2  # items 2, 4
        assert len(result["results"]) == 5  # All items accounted for


@pytest.mark.unit
class TestErrorReporting:
    """Test error reporting and logging."""

    def test_error_context_collection(self):
        """Test collection of error context information."""

        def collect_error_context(error, request_info=None):
            context = {
                "error_type": type(error).__name__,
                "error_message": str(error),
                "timestamp": time.time(),
                "request_info": request_info or {},
            }

            # Add stack trace in real implementation
            context["traceback"] = "Mock traceback"

            return context

        error = ValueError("Invalid input")
        request_info = {"provider": "openai", "model": "gpt-4", "prompt": "test prompt"}

        context = collect_error_context(error, request_info)

        assert context["error_type"] == "ValueError"
        assert context["error_message"] == "Invalid input"
        assert context["request_info"]["provider"] == "openai"
        assert "timestamp" in context

    def test_error_aggregation(self):
        """Test error aggregation and statistics."""

        class ErrorTracker:
            def __init__(self):
                self.errors = []

            def record_error(self, error_type, provider=None):
                self.errors.append(
                    {"type": error_type, "provider": provider, "timestamp": time.time()}
                )

            def get_error_stats(self, time_window=3600):  # 1 hour
                current_time = time.time()
                recent_errors = [
                    e for e in self.errors if current_time - e["timestamp"] <= time_window
                ]

                stats = {}
                for error in recent_errors:
                    key = f"{error['provider']}:{error['type']}"
                    stats[key] = stats.get(key, 0) + 1

                return {
                    "total_errors": len(recent_errors),
                    "error_breakdown": stats,
                    "time_window": time_window,
                }

        tracker = ErrorTracker()

        # Record some errors
        tracker.record_error("rate_limit", "openai")
        tracker.record_error("rate_limit", "openai")
        tracker.record_error("timeout", "anthropic")

        stats = tracker.get_error_stats()

        assert stats["total_errors"] == 3
        assert stats["error_breakdown"]["openai:rate_limit"] == 2
        assert stats["error_breakdown"]["anthropic:timeout"] == 1

    def test_error_notification_rules(self):
        """Test error notification trigger rules."""

        def should_notify(error_stats, rules):
            notifications = []

            for rule in rules:
                if rule["type"] == "error_rate":
                    error_rate = error_stats["total_errors"] / (
                        rule["time_window"] / 60
                    )  # per minute
                    if error_rate > rule["threshold"]:
                        notifications.append(
                            {
                                "rule": rule["name"],
                                "current_rate": error_rate,
                                "threshold": rule["threshold"],
                            }
                        )

                elif rule["type"] == "specific_error":
                    error_key = f"{rule['provider']}:{rule['error_type']}"
                    count = error_stats["error_breakdown"].get(error_key, 0)
                    if count >= rule["threshold"]:
                        notifications.append(
                            {
                                "rule": rule["name"],
                                "current_count": count,
                                "threshold": rule["threshold"],
                            }
                        )

            return notifications

        error_stats = {
            "total_errors": 10,
            "error_breakdown": {"openai:rate_limit": 5, "anthropic:timeout": 2},
            "time_window": 600,  # 10 minutes
        }

        rules = [
            {
                "name": "High error rate",
                "type": "error_rate",
                "threshold": 0.5,  # 0.5 errors per minute
                "time_window": 600,
            },
            {
                "name": "OpenAI rate limiting",
                "type": "specific_error",
                "provider": "openai",
                "error_type": "rate_limit",
                "threshold": 3,
            },
        ]

        notifications = should_notify(error_stats, rules)

        assert len(notifications) == 2
        assert notifications[0]["rule"] == "High error rate"
        assert notifications[1]["rule"] == "OpenAI rate limiting"


@pytest.mark.integration
class TestErrorHandlingIntegration:
    """Test integrated error handling flows."""

    def test_end_to_end_error_recovery(self, mock_all_providers):
        """Test complete error recovery workflow."""
        # Set up provider failures
        mock_all_providers["openai"].generate = Mock(side_effect=Exception("OpenAI down"))
        mock_all_providers["anthropic"].generate = Mock(return_value="Anthropic response")
        mock_all_providers["google"].generate = Mock(return_value="Google response")

        def robust_generate(prompt, providers):
            errors = []

            for provider_name, provider in providers.items():
                try:
                    response = provider.generate(prompt)
                    return {
                        "success": True,
                        "response": response,
                        "provider": provider_name,
                        "errors": errors,
                    }
                except Exception as e:
                    errors.append({"provider": provider_name, "error": str(e)})
                    continue

            return {"success": False, "response": None, "provider": None, "errors": errors}

        result = robust_generate("Test prompt", mock_all_providers)

        assert result["success"] == True
        assert result["provider"] == "anthropic"  # First working provider
        assert len(result["errors"]) == 1  # One failure recorded
        assert result["errors"][0]["provider"] == "openai"

    @pytest.mark.slow
    def test_recovery_under_load(self, mock_openai_provider):
        """Test error recovery under high load conditions."""
        # Simulate increasing failure rate under load
        request_count = 0

        def simulate_load_failures():
            nonlocal request_count
            request_count += 1

            # Failure rate increases with load
            failure_rate = min(0.8, request_count * 0.1)

            import random

            if random.random() < failure_rate:
                raise Exception(f"Load failure {request_count}")

            return f"Success {request_count}"

        # Test recovery with multiple attempts
        successes = 0
        failures = 0

        for i in range(20):
            try:
                result = simulate_load_failures()
                successes += 1
            except Exception:
                failures += 1

        # Should have some failures due to increasing load
        assert failures > 0
        assert successes > 0  # But not complete failure
        assert failures + successes == 20
